Workbook

Sheet Resumen
A1: Base sintética para algoritmo de matching — Sarasvati
A2: Perfiles falsos para pruebas del MVP. Incluye 20 creativos, 5 MiPymes, criterios defendibles, matriz de emparejamiento y Top 3 por caso.
A4: Indicador | B4: Valor | D4: Idea clave
A5: Creativos sintéticos | B5: 20 | D5: El match no debe premiar solo portafolio o precio, sino compatibilidad operativa entre necesidad, presupuesto, guía requerida, tiempos y cobertura real del servicio.
A6: MiPymes sintéticas | B6: 5 | D6: Qué cuenta como 'match perfecto'
A7: Emparejamientos evaluados | B7: 100 | D7: 1) Cubre los frentes críticos del proyecto.
A8: Criterios medibles hoy | B8: 8 | D8: 2) Puede trabajar dentro del presupuesto o sabe cotizarlo sin fricción.
D9: 3) Su forma de trabajar encaja con el nivel de acompañamiento que necesita la MiPyme.
D10: 4) No depende de datos que aún no capturas (reseñas, ciudad, calidad real del portafolio).
A11: Notas de uso
A12: • Usa Pairings_100 para ver el score completo y ajustar pesos.
A13: • Usa Top3_por_MiPyme para demos rápidas dentro del MVP.
A14: • Si una MiPyme prioriza ciudad o reseñas, el algoritmo debe pedir validación manual adicional.
A15: • Si el servicio mínimo cubierto es bajo, la plataforma debería sugerir alcance por fases o un segundo perfil.
A16: • Los datos son sintéticos y solo sirven para prototipado / pruebas internas.

Sheet Creativos_20
A1: Creativos sintéticos (20)
A2: Respuestas falsas pero coherentes con el diagnóstico creativo actual. Las columnas finales son derivadas y sirven como insumos del algoritmo.
A4: ID | B4: Alias | C4: Area principal | D4: Años exp | E4: Experiencia con MiPymes | F4: Sectores con experiencia | G4: Claridad briefs | H4: Fricciones frecuentes | I4: % >2 ajustes | J4: Criterios para aceptar | K4: Rango precio | L4: Proyectos simultáneos | M4: Modalidad | N4: Herramientas | O4: Portafolio | P4: Que espera de Sarasvati | Q4: Servicios que puede cubrir | R4: Índice guía | S4: Score herramientas | T4: Score experiencia | U4: Señal portafolio
A5: C01 | B5: Ana Torres | C5: Diseño gráfico,Branding / identidad de marca,Copywriting / redacción | D5: Más de 5 | E5: Sí, principal | F5: Gastronomía / alimentos,Moda / belleza, Comercio / retail | G5: A veces claros, a veces no | H5: Feedback confuso o contradictorio, Cambios de alcance sin ajuste de precio,Falta de materiales del cliente | I5: Entre 20% y 50% | J5: Que el brief sea claro, Que el presupuesto sea justo, Que el cliente esté abierto a mis propuestas, Que haya un proceso de feedback definido | K5: $1.000.000 – $3.000.000 | L5: 3–4 | M5: Me adapto | N5: WhatsApp,Google Drive / Wetransfer,Correo electrónico,Trello / Notion / Asana,Reuniones por Zoom/Meet | O5: Instagram, Behance / Dribbble, Página web propia | P5: Traerme clientes con briefs claros, Filtrar proyectos que encajen con mi perfil, Darme visibilidad ante MiPymes, Reducir retrabajos y rondas innecesarias | Q5: Branding / identidad de marca, Copywriting / textos, Diseño gráfico | R5: 0.98 | S5: 1 | T5: 1 | U5: 1
A6: C02 | B6: Julián Mejía | C6: Video,Motion graphics,Fotografía | D6: 3–5 | E6: Sí, entre otros | F6: Gastronomía / alimentos, Moda / belleza,Turismo / hotelería | G6: La mayoría llegan incompletos o confusos | H6: Tiempos de entrega irreales,Cambios de alcance sin ajuste de precio,Falta de materiales del cliente | I6: Más del 50% | J6: Que el presupuesto sea justo, Que el plazo sea realista, Que el sector me interese, Que el cliente esté abierto a mis propuestas | K6: $1.000.000 – $3.000.000 | L6: 1–2 | M6: Presencial cuando sea necesario | N6: WhatsApp,Google Drive / Wetransfer,Reuniones por Zoom/Meet | O6: Instagram, TikTok | P6: Traerme clientes con briefs claros, Filtrar proyectos que encajen con mi perfil, Proteger mis condiciones de trabajo, Reducir retrabajos y rondas innecesarias | Q6: Fotografía de producto o marca, Video / reels / animación | R6: 0.54 | S6: 0.95 | T6: 0.9 | U6: 1
A7: C03 | B7: Laura Ospina | C7: Diseño web / UI,Estrategia de marketing / contenido,Copywriting / redacción | D7: Más de 5 | E7: Sí, principal | F7: Tecnología,Educación,Servicios profesionales | G7: A veces claros, a veces no | H7: Brief incompleto o ambiguo,Feedback confuso o contradictorio,Expectativas no alineadas con el presupuesto | I7: Entre 20% y 50% | J7: Que el brief sea claro, Que el presupuesto sea justo, Que haya un proceso de feedback definido, Que sea un proyecto recurrente o de largo plazo | K7: $3.000.000 – $5.000.000 | L7: 1–2 | M7: 100% remoto | N7: Correo electrónico,Google Drive / Wetransfer,Trello / Notion / Asana,Reuniones por Zoom/Meet | O7: Página web propia, LinkedIn | P7: Traerme clientes con briefs claros, Filtrar proyectos que encajen con mi perfil, Ayudarme a cotizar mejor, Darme herramientas para gestionar proyectos | Q7: Copywriting / textos, Diseño web o landing page, Estrategia de contenido o marketing | R7: 0.93 | S7: 0.95 | T7: 1 | U7: 1
A8: C04 | B8: Mateo Rojas | C8: Contenido para redes (Community Management),Diseño gráfico,Estrategia de marketing / contenido | D8: 1–3 | E8: Sí, principal | F8: Comercio / retail,Gastronomía / alimentos,Moda / belleza | G8: Casi nunca recibo un brief formal | H8: Brief incompleto o ambiguo,Feedback confuso o contradictorio,Demora en pagos | I8: Casi todos | J8: Que el presupuesto sea justo, Que el sector me interese, Que el cliente esté abierto a mis propuestas, Que sea un proyecto recurrente o de largo plazo | K8: Menos de $500.000 COP | L8: 5+ | M8: 100% remoto | N8: WhatsApp, Google Drive / Wetransfer, Correo electrónico, Reuniones por Zoom/Meet | O8: Instagram, LinkedIn | P8: Traerme clientes con briefs claros, Darme visibilidad ante MiPymes, Ayudarme a cotizar mejor, Reducir retrabajos y rondas innecesarias | Q8: Contenido para redes sociales, Diseño gráfico, Estrategia de contenido o marketing | R8: 0.74 | S8: 1 | T8: 0.75 | U8: 1
A9: C05 | B9: Valentina Ruiz | C9: Branding / identidad de marca,Packaging,Ilustración | D9: 3–5 | E9: Sí, entre otros | F9: Moda / belleza,Gastronomía / alimentos,Comercio / retail | G9: A veces claros, a veces no | H9: Demasiadas rondas de ajustes,Expectativas no alineadas con el presupuesto,Falta de materiales del cliente | I9: Entre 20% y 50% | J9: Que el brief sea claro, Que el presupuesto sea justo, Que el sector me interese, Que haya un proceso de feedback definido | K9: $3.000.000 – $5.000.000 | L9: 1–2 | M9: Híbrido | N9: Correo electrónico, Google Drive / Wetransfer, Reuniones por Zoom/Meet | O9: Behance / Dribbble, Instagram, Página web propia | P9: Traerme clientes con briefs claros, Filtrar proyectos que encajen con mi perfil, Proteger mis condiciones de trabajo, Reducir retrabajos y rondas innecesarias | Q9: Branding / identidad de marca, Diseño gráfico, Packaging / diseño de empaques | R9: 0.7 | S9: 0.85 | T9: 0.9 | U9: 1
A10: C06 | B10: Camilo Herrera | C10: Fotografía,Video | D10: 1–3 | E10: Pocas veces | F10: Gastronomía / alimentos,Turismo / hotelería,Otro | G10: La mayoría llegan incompletos o confusos | H10: Tiempos de entrega irreales,Falta de materiales del cliente,Demora en pagos | I10: Más del 50% | J10: Que el presupuesto sea justo, Que el plazo sea realista, Que el sector me interese | K10: $500.000 – $1.000.000 | L10: 1–2 | M10: Presencial cuando sea necesario | N10: WhatsApp, Google Drive / Wetransfer, Reuniones por Zoom/Meet | O10: Instagram | P10: Traerme clientes con briefs claros, Darme visibilidad ante MiPymes, Proteger mis condiciones de trabajo | Q10: Fotografía de producto o marca, Video / reels / animación | R10: 0.31 | S10: 0.95 | T10: 0.6 | U10: 1
A11: C07 | B11: Sofía Marín | C11: Copywriting / redacción,Estrategia de marketing / contenido,Contenido para redes (Community Management) | D11: Más de 5 | E11: Sí, entre otros | F11: Salud / bienestar,Educación,Servicios profesionales | G11: A veces claros, a veces no | H11: Brief incompleto o ambiguo,Feedback confuso o contradictorio,Muchos aprobadores | I11: Entre 20% y 50% | J11: Que el brief sea claro, Que el sector me interese, Que el cliente esté abierto a mis propuestas, Que haya un proceso de feedback definido | K11: $1.000.000 – $3.000.000 | L11: 3–4 | M11: 100% remoto | N11: WhatsApp, Correo electrónico, Google Drive / Wetransfer, Reuniones por Zoom/Meet, Slack / Discord | O11: LinkedIn, Página web propia | P11: Traerme clientes con briefs claros, Filtrar proyectos que encajen con mi perfil, Darme herramientas para gestionar proyectos, Capacitarme para mejorar nis habilidades | Q11: Contenido para redes sociales, Copywriting / textos, Estrategia de contenido o marketing | R11: 0.86 | S11: 1 | T11: 1 | U11: 1
A12: C08 | B12: Nicolás Pardo | C12: Diseño gráfico,Motion graphics,Video | D12: 3–5 | E12: Sí, entre otros | F12: Tecnología, Comercio / retail,Cualquier sector | G12: A veces claros, a veces no | H12: Feedback confuso o contradictorio,Tiempos de entrega irreales,Cambios de alcance sin ajuste de precio | I12: Entre 20% y 50% | J12: Que el presupuesto sea justo, Que el plazo sea realista, Que el cliente esté abierto a mis propuestas | K12: $1.000.000 – $3.000.000 | L12: 3–4 | M12: Híbrido | N12: WhatsApp, Google Drive / Wetransfer, Correo electrónico, Reuniones por Zoom/Meet | O12: Behance / Dribbble, Instagram, LinkedIn | P12: Traerme clientes con briefs claros, Filtrar proyectos que encajen con mi perfil, Darme visibilidad ante MiPymes | Q12: Diseño gráfico, Video / reels / animación | R12: 0.54 | S12: 1 | T12: 0.9 | U12: 1
A13: C09 | B13: Daniela Vélez | C13: Diseño web / UI,Branding / identidad de marca | D13: Más de 5 | E13: Sí, entre otros | F13: Tecnología,Educación,Servicios profesionales | G13: Casi siempre llegan claros y completos | H13: Expectativas no alineadas con el presupuesto,Cambios de alcance sin ajuste de precio,Muchos aprobadores | I13: Menos del 20% | J13: Que el brief sea claro, Que el presupuesto sea justo, Que el plazo sea realista, Que haya un proceso de feedback definido | K13: $5.000.000 - $10.000.000 | L13: 1–2 | M13: 100% remoto | N13: Correo electrónico, Google Drive / Wetransfer, Trello / Notion / Asana, Reuniones por Zoom/Meet | O13: Página web propia, LinkedIn, Behance / Dribbble | P13: Filtrar proyectos que encajen con mi perfil, Ayudarme a cotizar mejor, Proteger mis condiciones de trabajo | Q13: Branding / identidad de marca, Diseño web o landing page | R13: 0.85 | S13: 0.95 | T13: 1 | U13: 1
A14: C10 | B14: Felipe Gómez | C14: Packaging,Diseño gráfico,Fotografía | D14: 3–5 | E14: Sí,principal | F14: Gastronomía / alimentos,Comercio / retail,Moda / belleza | G14: A veces claros, a veces no | H14: Falta de materiales del cliente (fotos, logos, textos),Demasiadas rondas de ajustes,Demora en pagos | I14: Entre 20% y 50% | J14: Que el presupuesto sea justo, Que el sector me interese, Que el plazo sea realista, Que el cliente esté abierto a mis propuestas | K14: $1.000.000 – $3.000.000 | L14: 3–4 | M14: Híbrido | N14: WhatsApp, Google Drive / Wetransfer, Correo electrónico, Reuniones por Zoom/Meet | O14: Instagram, Behance / Dribbble | P14: Traerme clientes con briefs claros, Filtrar proyectos que encajen con mi perfil, Darme visibilidad ante MiPymes, Reducir retrabajos y rondas innecesarias | Q14: Diseño gráfico, Fotografía de producto o marca, Packaging / diseño de empaques | R14: 0.62 | S14: 1 | T14: 0.98 | U14: 1
A15: C11 | B15: Mariana Salcedo | C15: Branding / identidad de marca,Copywriting / redacción,Estrategia de marketing / contenido | D15: 1–3 | E15: Sí,principal | F15: Cualquier sector | G15: La mayoría llegan incompletos o confusos | H15: Brief incompleto o ambiguo,Feedback confuso o contradictorio,Cambios de alcance sin ajuste de precio | I15: Más del 50% | J15: Que el presupuesto sea justo, Que el cliente esté abierto a mis propuestas, Que haya un proceso de feedback definido, Que sea un proyecto recurrente o de largo plazo | K15: $500.000 – $1.000.000 | L15: 3–4 | M15: Me adapto | N15: WhatsApp, Google Drive / Wetransfer, Correo electrónico, Reuniones por Zoom/Meet, Trello / Notion / Asana | O15: Instagram, LinkedIn | P15: Traerme clientes con briefs claros, Darme visibilidad ante MiPymes, Ayudarme a cotizar mejor, Capacitarme para mejorar nis habilidades | Q15: Branding / identidad de marca, Copywriting / textos, Estrategia de contenido o marketing | R15: 0.86 | S15: 1 | T15: 0.75 | U15: 1
A16: C12 | B16: Andrés Buitrago | C16: Video,Motion graphics,Contenido para redes (Community Management) | D16: Más de 5 | E16: Sí, entre otros | F16: Tecnología,Educación,Servicios profesionales | G16: A veces claros, a veces no | H16: Tiempos de entrega irreales,Feedback confuso o contradictorio,Muchos aprobadores | I16: Entre 20% y 50% | J16: Que el brief sea claro, Que el plazo sea realista, Que el presupuesto sea justo, Que el cliente esté abierto a mis propuestas | K16: $3.000.000 – $5.000.000 | L16: 1–2 | M16: 100% remoto | N16: Slack / Discord, Trello / Notion / Asana, Correo electrónico, Reuniones por Zoom/Meet, Google Drive / Wetransfer | O16: Behance / Dribbble, Página web propia, LinkedIn | P16: Traerme clientes con briefs claros, Filtrar proyectos que encajen con mi perfil, Darme herramientas para gestionar proyectos | Q16: Contenido para redes sociales, Video / reels / animación | R16: 0.82 | S16: 1 | T16: 1 | U16: 1
... A24: C20 | B24: Tomás Jaramillo | C24: Diseño web / UI,Branding / identidad de marca,Diseño gráfico | D24: Más de 5 | E24: Sí, entre otros | F24: Tecnología,Comercio / retail,Servicios profesionales,Cualquier sector | G24: Casi siempre llegan claros y completos | H24: Cambios de alcance sin ajuste de precio,Expectativas no alineadas con el presupuesto,Muchos aprobadores | I24: Menos del 20% | J24: Que el brief sea claro, Que el presupuesto sea justo, Que el plazo sea realista, Que haya un proceso de feedback definido | K24: $3.000.000 – $5.000.000 | L24: 1–2 | M24: 100% remoto | N24: Correo electrónico, Google Drive / Wetransfer, Trello / Notion / Asana, Reuniones por Zoom/Meet | O24: Página web propia, Behance / Dribbble, LinkedIn | P24: Filtrar proyectos que encajen con mi perfil, Ayudarme a cotizar mejor, Proteger mis condiciones de trabajo | Q24: Branding / identidad de marca, Diseño gráfico, Diseño web o landing page | R24: 0.85 | S24: 0.95 | T24: 1 | U24: 1

Sheet MiPymes_5
A1: MiPymes sintéticas (5)
A2: Casos de prueba que representan distintos niveles de claridad, madurez digital, presupuesto y necesidad de acompañamiento.
A4: ID | B4: Empresa | C4: Empleados | D4: Sector | E4: Años operando | F4: Presencia digital | G4: Apoyo creativo | H4: Objetivo | I4: Plazo | J4: Presupuesto | K4: Experiencia previa | L4: Dificultades previas | M4: Claridad actual | N4: Top 3 al elegir | O4: Materiales listos | P4: Índice guía requerido | Q4: Cantidad de frentes
A5: M01 | B5: Café de Barrio | C5: 1–5 | D5: Gastronomía / alimentos | E5: 1–3 | F5: Solo redes sociales (pero las manejo) | G5: Contenido para redes sociales, Fotografía de producto o marca, Estrategia de contenido o marketing | H5: Aumentar ventas o conversiones | I5: 2–3,semanas | J5: $1.000.000 – $3.000.000 | K5: Una o dos veces | L5: Explicar bien lo que necesitaba, El resultado no fue lo que esperaba, Dar feedback claro | M5: Tengo una idea general pero me falta aterrizar | N5: Que entienda mi negocio y mi sector,Que me guíe en el proceso,Rapidez de entrega | O5: Fotos de mis productos/servicios,Textos o información del negocio | P5: 0.72 | Q5: 3
A6: M02 | B6: Dermalab Natural | C6: 6–20 | D6: Salud / bienestar | E6: 3–5 | F6: Tengo redes activas y página web | G6: Branding / identidad de marca, Packaging / diseño de empaques, Copywriting / textos | H6: Mejorar, rediseñar o refrescar mi marca | I6: 1–2,meses | J6: $3.000.000 – $5.000.000 | K6: Sí, varias veces (freelancers o agencias) | L6: Muchos retrabajos y rondas de ajustes, Dar feedback claro, Comparar opciones entre creativos | M6: Muy claro, sé exactamente qué pedir | N6: Calidad del portafolio,Experiencia comprobable,Que entienda mi negocio y mi sector | O6: Logo y guía de marca,Textos o información del negocio,Referencias visuales de lo que me gusta,Presupuesto definido | P6: 0.1 | Q6: 3
A7: M03 | B7: EduPlay Lab | C7: 1–5 | D7: Educación | E7: Menos de 1 | F7: Muy básica o desactualizada | G7: Diseño web o landing page, Copywriting / textos, Estrategia de contenido o marketing, No tengo claro aún | H7: Lanzar un producto o servicio nuevo | I7: sin prisa | J7: no se | K7: Nunca | L7: No aplica (nunca he contratado) | M7: Sé que necesito algo pero no sé qué exactamente | N7: Que me guíe en el proceso,Precio,Que entienda mi negocio y mi sector | O7: Textos o información del negocio | P7: 1 | Q7: 3
A8: M04 | B8: OptiSoft Analytics | C8: 21–50 | D8: Tecnología / software | E8: Más de 5 | F8: Tengo redes activas y página web | G8: Video / reels / animación, Diseño web o landing page, Estrategia de contenido o marketing | H8: Lanzar un producto o servicio nuevo | I8: 2-3,semanas | J8: $5.000.000 - $10.000.000 | K8: Sí, varias veces (freelancers o agencias) | L8: Problemas con tiempos de entrega, Comparar opciones entre creativos, El resultado no fue lo que esperaba | M8: Muy claro, sé exactamente qué pedir | N8: Rapidez de entrega,Experiencia comprobable,Calidad del portafolio | O8: Logo y guía de marca, Textos o información del negocio,Referencias visuales de lo que me gusta,Presupuesto definido | P8: 0.1 | Q8: 3
A9: M05 | B9: Ruta Nativa Hotel | C9: 6–20 | D9: Turismo / hotelería | E9: 1–3 | F9: Tengo redes pero casi no publico | G9: Branding / identidad de marca, Contenido para redes sociales, Fotografía de producto o marca | H9: Profesionalizar mi imagen | I9: 1-2,meses | J9: no se | K9: Solo con conocidos o referidos | L9: Encontrar al creativo adecuado, Explicar bien lo que necesitaba, Comparar opciones entre creativos | M9: Estoy explorando opciones | N9: Que entienda mi negocio y mi sector,Que me guíe en el proceso,Que esté en mi ciudad | O9: Fotos de mis productos/servicios,Textos o información del negocio | P9: 1 | Q9: 3

Sheet Criterios_Match
A1: Lógica de matching defendible
A2: La matriz separa criterios medibles hoy vs. señales importantes que aún no están bien capturadas en el diagnóstico.
A4: Criterio | B4: Por qué importa | C4: Peso base | D4: Cómo usarlo | F4: Señal submedida hoy | G4: Por qué NO debería pesar aún | H4: Qué hacer | I4: Estado
A5: Cobertura de servicio | B5: Mide si el creativo cubre los frentes que la MiPyme pidió. Debe pesar más que cualquier otro criterio. | C5: 30 | D5: Promedio del encaje por servicio solicitado; no debe quedar por debajo de la cobertura mínima esperada. | F5: Ciudad del creativo | G5: La MiPyme puede priorizar 'que esté en mi ciudad', pero el diagnóstico creativo actual no recoge ciudad. | H5: Usarlo como filtro manual o agregar un campo de ciudad. | I5: Manual / futura iteración
A6: Encaje de presupuesto | B6: Evita matches inviables por precio y protege la confianza desde el inicio. | C6: 18 | D6: Comparar banda de presupuesto vs. rango habitual del creativo. | F6: Reseñas / referencias verificadas | G6: Hoy la MiPyme puede valorar reseñas, pero el input creativo no las captura. | H6: No ponderarlo todavía; dejarlo para fase 2. | I6: Manual / futura iteración
A7: Acompañamiento / proceso | B7: Captura si la MiPyme necesita guía y si el creativo tiene perfil para aterrizar briefs. | C7: 14 | D7: Cruzar qué tanta guía necesita la MiPyme con la capacidad de acompañamiento del creativo. | F7: Calidad real del portafolio | G7: El diagnóstico solo dice dónde publica el portafolio, no qué tan fuerte es. | H7: Usar apenas una señal débil de visibilidad, no de calidad. | I7: Manual / futura iteración
A8: Encaje con urgencia/capacidad | B8: Reduce promesas imposibles y fricciones por tiempos de entrega. | C8: 14 | D8: Cruzar el plazo con la capacidad operativa declarada. | F8: Disponibilidad exacta por semana | G8: El diagnóstico pregunta cuántos proyectos maneja, pero no su calendario exacto. | H8: Mantenerlo como proxy y validar manualmente. | I8: Manual / futura iteración
A9: Familiaridad sectorial | B9: Ayuda a reducir curva de aprendizaje cuando la MiPyme valora contexto de negocio. | C9: 9 | D9: Tomarlo como acelerador, no como sustituto de la cobertura del servicio.
A10: Experiencia vs complejidad | B10: Evita asignar perfiles junior a encargos demasiado complejos o caros. | C10: 6 | D10: Más útil cuando el proyecto es caro, tiene varios frentes o implica rediseño/lanzamiento.
A11: Modalidad / adaptabilidad | B11: Importa más cuando hay foto, presencialidad o preferencia local. | C11: 4 | D11: Sube de importancia si hay foto, presencialidad o prioridad local.
A12: Comunicación / herramientas | B12: Aumenta operatividad; especialmente útil para MiPymes poco maduras digitalmente. | C12: 5 | D12: Sirve para reducir fricción operativa y de feedback.
D14: =SUM(C4:C12) -> 100
A15: Reglas para marcar un candidato casi perfecto
A16: 1) Cobertura media de servicio >= 0.65.
A17: 2) Cobertura mínima por frente >= 0.40 (si no, sugerir segundo perfil o alcance por fases).
A18: 3) El presupuesto no debe desalinearse más de una banda.
A19: 4) Si la MiPyme necesita mucha guía, el creativo debe tener alto índice de acompañamiento.
A20: 5) Si la MiPyme prioriza ciudad o reseñas, el resultado debe quedar en revisión manual.

Sheet Pairings_100
A1: Matriz completa de emparejamientos
A2: Cada fila cruza 1 MiPyme con 1 creativo. Los raw fits van de 0 a 1; los puntos ponderados se calculan por fórmula para que puedas ajustar pesos después.
A4: MiPyme_ID | B4: Empresa | C4: Creativo_ID | D4: Creativo | E4: Service_fit_raw | F4: Service_min_raw | G4: Budget_fit_raw | H4: Guidance_fit_raw | I4: Urgency_fit_raw | J4: Sector_fit_raw | K4: Experience_fit_raw | L4: Modality_fit_raw | M4: Comms_fit_raw | N4: Priority_bonus_pts | O4: Servicio_pts | P4: Presupuesto_pts | Q4: Guía_pts | R4: Urgencia_pts | S4: Sector_pts | T4: Experiencia_pts | U4: Modalidad_pts | V4: Comms_pts | W4: Total_score | X4: Rank_por_MiPyme | Y4: Estado | Z4: Razón 1 | AA4: Razón 2 | AB4: Razón 3 | AC4: Cautela
A5: M01 | B5: Café de Barrio | C5: C01 | D5: Ana Torres | E5: 0.33 | F5: 0 | G5: 1 | H5: 0.99 | I5: 0.75 | J5: 1 | K5: 1 | L5: 1 | M5: 1 | N5: 8.22 | O5: =E5*Criterios_Match!$C$5 -> 9.9 | P5: =G5*Criterios_Match!$C$6 -> 18 | Q5: =H5*Criterios_Match!$C$7 -> 13.86 | R5: =I5*Criterios_Match!$C$8 -> 10.5 | S5: =J5*Criterios_Match!$C$9 -> 9 | T5: =K5*Criterios_Match!$C$10 -> 6 | U5: =L5*Criterios_Match!$C$11 -> 4 | V5: =M5*Criterios_Match!$C$12 -> 5 | W5: =ROUND(SUM(O5:V5)+N5,2) -> 84.48 | X5: =COUNTIFS($A$5:$A$104,A5,$W$5:$W$104,">"&W5)+1 -> 5 | Y5: Opción parcial / revisar alcance | Z5: Ya ha trabajado en Gastronomía / alimentos. | AA5: El presupuesto encaja con su rango habitual. | AB5: Puede acompañar a una MiPyme que aún está aterrizando el encargo. | AC5: No cubre de forma sólida uno de los frentes solicitados; podría requerir segundo perfil o alcance por fases.
A6: M01 | B6: Café de Barrio | C6: C02 | D6: Julián Mejía | E6: 0.5 | F6: 0 | G6: 1 | H6: 0.82 | I6: 0.95 | J6: 1 | K6: 0.96 | L6: 1 | M6: 0.95 | N6: 8.31 | O6: =E6*Criterios_Match!$C$5 -> 15 | P6: =G6*Criterios_Match!$C$6 -> 18 | Q6: =H6*Criterios_Match!$C$7 -> 11.48 | R6: =I6*Criterios_Match!$C$8 -> 13.3 | S6: =J6*Criterios_Match!$C$9 -> 9 | T6: =K6*Criterios_Match!$C$10 -> 5.76 | U6: =L6*Criterios_Match!$C$11 -> 4 | V6: =M6*Criterios_Match!$C$12 -> 4.75 | W6: =ROUND(SUM(O6:V6)+N6,2) -> 89.6 | X6: =COUNTIFS($A$5:$A$104,A6,$W$5:$W$104,">"&W6)+1 -> 2 | Y6: Opción parcial / revisar alcance | Z6: Tiene cobertura razonable para el alcance actual. | AA6: Ya ha trabajado en Gastronomía / alimentos. | AB6: El presupuesto encaja con su rango habitual. | AC6: No cubre de forma sólida uno de los frentes solicitados; podría requerir segundo perfil o alcance por fases.
A7: M01 | B7: Café de Barrio | C7: C03 | D7: Laura Ospina | E7: 0.48 | F7: 0 | G7: 0.75 | H7: 0.97 | I7: 0.7 | J7: 0.25 | K7: 1 | L7: 0.4 | M7: 0.95 | N7: 5.76 | O7: =E7*Criterios_Match!$C$5 -> 14.4 | P7: =G7*Criterios_Match!$C$6 -> 13.5 | Q7: =H7*Criterios_Match!$C$7 -> 13.58 | R7: =I7*Criterios_Match!$C$8 -> 9.8 | S7: =J7*Criterios_Match!$C$9 -> 2.25 | T7: =K7*Criterios_Match!$C$10 -> 6 | U7: =L7*Criterios_Match!$C$11 -> 1.6 | V7: =M7*Criterios_Match!$C$12 -> 4.75 | W7: =ROUND(SUM(O7:V7)+N7,2) -> 71.64 | X7: =COUNTIFS($A$5:$A$104,A7,$W$5:$W$104,">"&W7)+1 -> 16 | Y7: Opción parcial / revisar alcance | Z7: Tiene cobertura razonable para el alcance actual. | AA7: El presupuesto encaja con su rango habitual. | AB7: Puede acompañar a una MiPyme que aún está aterrizando el encargo. | AC7: No cubre de forma sólida uno de los frentes solicitados; podría requerir segundo perfil o alcance por fases.
A8: M01 | B8: Café de Barrio | C8: C04 | D8: Mateo Rojas | E8: 0.67 | F8: 0 | G8: 0.35 | H8: 0.9 | I8: 0.3 | J8: 1 | K8: 0.9 | L8: 0.4 | M8: 1 | N8: 6.6 | O8: =E8*Criterios_Match!$C$5 -> 20.1 | P8: =G8*Criterios_Match!$C$6 -> 6.3 | Q8: =H8*Criterios_Match!$C$7 -> 12.6 | R8: =I8*Criterios_Match!$C$8 -> 4.2 | S8: =J8*Criterios_Match!$C$9 -> 9 | T8: =K8*Criterios_Match!$C$10 -> 5.4 | U8: =L8*Criterios_Match!$C$11 -> 1.6 | V8: =M8*Criterios_Match!$C$12 -> 5 | W8: =ROUND(SUM(O8:V8)+N8,2) -> 70.8 | X8: =COUNTIFS($A$5:$A$104,A8,$W$5:$W$104,">"&W8)+1 -> 18 | Y8: Opción parcial / revisar alcance | Z8: Tiene cobertura razonable para el alcance actual. | AA8: Ya ha trabajado en Gastronomía / alimentos. | AB8: Puede acompañar a una MiPyme que aún está aterrizando el encargo. | AC8: No cubre de forma sólida uno de los frentes solicitados; podría requerir segundo perfil o alcance por fases.
A9: M01 | B9: Café de Barrio | C9: C05 | D9: Valentina Ruiz | E9: 0 | F9: 0 | G9: 0.75 | H9: 0.88 | I9: 0.95 | J9: 1 | K9: 0.96 | L9: 1 | M9: 0.85 | N9: 8.49 | O9: =E9*Criterios_Match!$C$5 -> 0 | P9: =G9*Criterios_Match!$C$6 -> 13.5 | Q9: =H9*Criterios_Match!$C$7 -> 12.32 | R9: =I9*Criterios_Match!$C$8 -> 13.3 | S9: =J9*Criterios_Match!$C$9 -> 9 | T9: =K9*Criterios_Match!$C$10 -> 5.76 | U9: =L9*Criterios_Match!$C$11 -> 4 | V9: =M9*Criterios_Match!$C$12 -> 4.25 | W9: =ROUND(SUM(O9:V9)+N9,2) -> 70.62 | X9: =COUNTIFS($A$5:$A$104,A9,$W$5:$W$104,">"&W9)+1 -> 19 | Y9: Opción parcial / revisar alcance | Z9: Ya ha trabajado en Gastronomía / alimentos. | AA9: El presupuesto encaja con su rango habitual. | AB9: Puede acompañar a una MiPyme que aún está aterrizando el encargo. | AC9: No cubre de forma sólida uno de los frentes solicitados; podría requerir segundo perfil o alcance por fases.
A10: M01 | B10: Café de Barrio | C10: C06 | D10: Camilo Herrera | E10: 0.5 | F10: 0 | G10: 0.75 | H10: 0.72 | I10: 0.95 | J10: 1 | K10: 0.84 | L10: 1 | M10: 0.95 | N10: 8.01 | O10: =E10*Criterios_Match!$C$5 -> 15 | P10: =G10*Criterios_Match!$C$6 -> 13.5 | Q10: =H10*Criterios_Match!$C$7 -> 10.08 | R10: =I10*Criterios_Match!$C$8 -> 13.3 | S10: =J10*Criterios_Match!$C$9 -> 9 | T10: =K10*Criterios_Match!$C$10 -> 5.04 | U10: =L10*Criterios_Match!$C$11 -> 4 | V10: =M10*Criterios_Match!$C$12 -> 4.75 | W10: =ROUND(SUM(O10:V10)+N10,2) -> 82.68 | X10: =COUNTIFS($A$5:$A$104,A10,$W$5:$W$104,">"&W10)+1 -> 6 | Y10: Opción parcial / revisar alcance | Z10: Tiene cobertura razonable para el alcance actual. | AA10: Ya ha trabajado en Gastronomía / alimentos. | AB10: El presupuesto encaja con su rango habitual. | AC10: No cubre de forma sólida uno de los frentes solicitados; podría requerir segundo perfil o alcance por fases.
A11: M01 | B11: Café de Barrio | C11: C07 | D11: Sofía Marín | E11: 0.67 | F11: 0 | G11: 1 | H11: 0.94 | I11: 0.5 | J11: 0.25 | K11: 1 | L11: 0.4 | M11: 1 | N11: 5.07 | O11: =E11*Criterios_Match!$C$5 -> 20.1 | P11: =G11*Criterios_Match!$C$6 -> 18 | Q11: =H11*Criterios_Match!$C$7 -> 13.16 | R11: =I11*Criterios_Match!$C$8 -> 7 | S11: =J11*Criterios_Match!$C$9 -> 2.25 | T11: =K11*Criterios_Match!$C$10 -> 6 | U11: =L11*Criterios_Match!$C$11 -> 1.6 | V11: =M11*Criterios_Match!$C$12 -> 5 | W11: =ROUND(SUM(O11:V11)+N11,2) -> 78.18 | X11: =COUNTIFS($A$5:$A$104,A11,$W$5:$W$104,">"&W11)+1 -> 10 | Y11: Opción parcial / revisar alcance | Z11: Tiene cobertura razonable para el alcance actual. | AA11: El presupuesto encaja con su rango habitual. | AB11: Puede acompañar a una MiPyme que aún está aterrizando el encargo. | AC11: No cubre de forma sólida uno de los frentes solicitados; podría requerir segundo perfil o alcance por fases.
A12: M01 | B12: Café de Barrio | C12: C08 | D12: Nicolás Pardo | E12: 0.27 | F12: 0 | G12: 1 | H12: 0.82 | I12: 0.75 | J12: 0.9 | K12: 0.96 | L12: 1 | M12: 1 | N12: 7.41 | O12: =E12*Criterios_Match!$C$5 -> 8.1 | P12: =G12*Criterios_Match!$C$6 -> 18 | Q12: =H12*Criterios_Match!$C$7 -> 11.48 | R12: =I12*Criterios_Match!$C$8 -> 10.5 | S12: =J12*Criterios_Match!$C$9 -> 8.1 | T12: =K12*Criterios_Match!$C$10 -> 5.76 | U12: =L12*Criterios_Match!$C$11 -> 4 | V12: =M12*Criterios_Match!$C$12 -> 5 | W12: =ROUND(SUM(O12:V12)+N12,2) -> 78.35 | X12: =COUNTIFS($A$5:$A$104,A12,$W$5:$W$104,">"&W12)+1 -> 9 | Y12: Opción parcial / revisar alcance | Z12: Ya ha trabajado en Gastronomía / alimentos. | AA12: El presupuesto encaja con su rango habitual. | AB12: Puede acompañar a una MiPyme que aún está aterrizando el encargo. | AC12: No cubre de forma sólida uno de los frentes solicitados; podría requerir segundo perfil o alcance por fases.
A13: M01 | B13: Café de Barrio | C13: C09 | D13: Daniela Vélez | E13: 0.05 | F13: 0 | G13: 0.35 | H13: 0.94 | I13: 0.7 | J13: 0.25 | K13: 1 | L13: 0.4 | M13: 0.95 | N13: 5.67 | O13: =E13*Criterios_Match!$C$5 -> 1.5 | P13: =G13*Criterios_Match!$C$6 -> 6.3 | Q13: =H13*Criterios_Match!$C$7 -> 13.16 | R13: =I13*Criterios_Match!$C$8 -> 9.8 | S13: =J13*Criterios_Match!$C$9 -> 2.25 | T13: =K13*Criterios_Match!$C$10 -> 6 | U13: =L13*Criterios_Match!$C$11 -> 1.6 | V13: =M13*Criterios_Match!$C$12 -> 4.75 | W13: =ROUND(SUM(O13:V13)+N13,2) -> 51.03 | X13: =COUNTIFS($A$5:$A$104,A13,$W$5:$W$104,">"&W13)+1 -> 20 | Y13: Opción parcial / revisar alcance | Z13: Puede acompañar a una MiPyme que aún está aterrizando el encargo. | AA13: Su experiencia calza con la complejidad del proyecto. | AC13: No cubre de forma sólida uno de los frentes solicitados; podría requerir segundo perfil o alcance por fases.
A14: M01 | B14: Café de Barrio | C14: C10 | D14: Felipe Gómez | E14: 0.53 | F14: 0 | G14: 1 | H14: 0.85 | I14: 0.75 | J14: 1 | K14: 0.99 | L14: 1 | M14: 1 | N14: 7.8 | O14: =E14*Criterios_Match!$C$5 -> 15.9 | P14: =G14*Criterios_Match!$C$6 -> 18 | Q14: =H14*Criterios_Match!$C$7 -> 11.9 | R14: =I14*Criterios_Match!$C$8 -> 10.5 | S14: =J14*Criterios_Match!$C$9 -> 9 | T14: =K14*Criterios_Match!$C$10 -> 5.94 | U14: =L14*Criterios_Match!$C$11 -> 4 | V14: =M14*Criterios_Match!$C$12 -> 5 | W14: =ROUND(SUM(O14:V14)+N14,2) -> 88.04 | X14: =COUNTIFS($A$5:$A$104,A14,$W$5:$W$104,">"&W14)+1 -> 3 | Y14: Opción parcial / revisar alcance | Z14: Tiene cobertura razonable para el alcance actual. | AA14: Ya ha trabajado en Gastronomía / alimentos. | AB14: El presupuesto encaja con su rango habitual. | AC14: No cubre de forma sólida uno de los frentes solicitados; podría requerir segundo perfil o alcance por fases.
A15: M01 | B15: Café de Barrio | C15: C11 | D15: Mariana Salcedo | E15: 0.48 | F15: 0 | G15: 0.75 | H15: 0.94 | I15: 0.75 | J15: 0.9 | K15: 0.9 | L15: 1 | M15: 1 | N15: 7.77 | O15: =E15*Criterios_Match!$C$5 -> 14.4 | P15: =G15*Criterios_Match!$C$6 -> 13.5 | Q15: =H15*Criterios_Match!$C$7 -> 13.16 | R15: =I15*Criterios_Match!$C$8 -> 10.5 | S15: =J15*Criterios_Match!$C$9 -> 8.1 | T15: =K15*Criterios_Match!$C$10 -> 5.4 | U15: =L15*Criterios_Match!$C$11 -> 4 | V15: =M15*Criterios_Match!$C$12 -> 5 | W15: =ROUND(SUM(O15:V15)+N15,2) -> 81.83 | X15: =COUNTIFS($A$5:$A$104,A15,$W$5:$W$104,">"&W15)+1 -> 7 | Y15: Opción parcial / revisar alcance | Z15: Tiene cobertura razonable para el alcance actual. | AA15: Ya ha trabajado en Gastronomía / alimentos. | AB15: El presupuesto encaja con su rango habitual. | AC15: No cubre de forma sólida uno de los frentes solicitados; podría requerir segundo perfil o alcance por fases.
A16: M01 | B16: Café de Barrio | C16: C12 | D16: Andrés Buitrago | E16: 0.58 | F16: 0.2 | G16: 0.75 | H16: 0.93 | I16: 0.7 | J16: 0.25 | K16: 1 | L16: 0.4 | M16: 1 | N16: 5.64 | O16: =E16*Criterios_Match!$C$5 -> 17.4 | P16: =G16*Criterios_Match!$C$6 -> 13.5 | Q16: =H16*Criterios_Match!$C$7 -> 13.02 | R16: =I16*Criterios_Match!$C$8 -> 9.8 | S16: =J16*Criterios_Match!$C$9 -> 2.25 | T16: =K16*Criterios_Match!$C$10 -> 6 | U16: =L16*Criterios_Match!$C$11 -> 1.6 | V16: =M16*Criterios_Match!$C$12 -> 5 | W16: =ROUND(SUM(O16:V16)+N16,2) -> 74.21 | X16: =COUNTIFS($A$5:$A$104,A16,$W$5:$W$104,">"&W16)+1 -> 12 | Y16: Opción parcial / revisar alcance | Z16: Tiene cobertura razonable para el alcance actual. | AA16: El presupuesto encaja con su rango habitual. | AB16: Puede acompañar a una MiPyme que aún está aterrizando el encargo. | AC16: No cubre de forma sólida uno de los frentes solicitados; podría requerir segundo perfil o alcance por fases.
A17: M01 | B17: Café de Barrio | C17: C13 | D17: Paula Restrepo | E17: 0.2 | F17: 0 | G17: 1 | H17: 0.85 | I17: 0.95 | J17: 1 | K17: 0.93 | L17: 1 | M17: 0.95 | N17: 8.4 | O17: =E17*Criterios_Match!$C$5 -> 6 | P17: =G17*Criterios_Match!$C$6 -> 18 | Q17: =H17*Criterios_Match!$C$7 -> 11.9 | R17: =I17*Criterios_Match!$C$8 -> 13.3 | S17: =J17*Criterios_Match!$C$9 -> 9 | T17: =K17*Criterios_Match!$C$10 -> 5.58 | U17: =L17*Criterios_Match!$C$11 -> 4 | V17: =M17*Criterios_Match!$C$12 -> 4.75 | W17: =ROUND(SUM(O17:V17)+N17,2) -> 80.93 | X17: =COUNTIFS($A$5:$A$104,A17,$W$5:$W$104,">"&W17)+1 -> 8 | Y17: Opción parcial / revisar alcance | Z17: Ya ha trabajado en Gastronomía / alimentos. | AA17: El presupuesto encaja con su rango habitual. | AB17: Puede acompañar a una MiPyme que aún está aterrizando el encargo. | AC17: No cubre de forma sólida uno de los frentes solicitados; podría requerir segundo perfil o alcance por fases.
A18: M01 | B18: Café de Barrio | C18: C14 | D18: Sergio Cárdenas | E18: 0.67 | F18: 0 | G18: 1 | H18: 0.96 | I18: 0.75 | J18: 1 | K18: 1 | L18: 1 | M18: 1 | N18: 8.13 | O18: =E18*Criterios_Match!$C$5 -> 20.1 | P18: =G18*Criterios_Match!$C$6 -> 18 | Q18: =H18*Criterios_Match!$C$7 -> 13.44 | R18: =I18*Criterios_Match!$C$8 -> 10.5 | S18: =J18*Criterios_Match!$C$9 -> 9 | T18: =K18*Criterios_Match!$C$10 -> 6 | U18: =L18*Criterios_Match!$C$11 -> 4 | V18: =M18*Criterios_Match!$C$12 -> 5 | W18: =ROUND(SUM(O18:V18)+N18,2) -> 94.17 | X18: =COUNTIFS($A$5:$A$104,A18,$W$5:$W$104,">"&W18)+1 -> 1 | Y18: Opción parcial / revisar alcance | Z18: Tiene cobertura razonable para el alcance actual. | AA18: Ya ha trabajado en Gastronomía / alimentos. | AB18: El presupuesto encaja con su rango habitual. | AC18: No cubre de forma sólida uno de los frentes solicitados; podría requerir segundo perfil o alcance por fases.
A19: M01 | B19: Café de Barrio | C19: C15 | D19: Luisa Fernanda Gil | E19: 0.48 | F19: 0 | G19: 1 | H19: 0.99 | I19: 0.7 | J19: 0.25 | K19: 0.99 | L19: 0.4 | M19: 0.95 | N19: 5.82 | O19: =E19*Criterios_Match!$C$5 -> 14.4 | P19: =G19*Criterios_Match!$C$6 -> 18 | Q19: =H19*Criterios_Match!$C$7 -> 13.86 | R19: =I19*Criterios_Match!$C$8 -> 9.8 | S19: =J19*Criterios_Match!$C$9 -> 2.25 | T19: =K19*Criterios_Match!$C$10 -> 5.94 | U19: =L19*Criterios_Match!$C$11 -> 1.6 | V19: =M19*Criterios_Match!$C$12 -> 4.75 | W19: =ROUND(SUM(O19:V19)+N19,2) -> 76.42 | X19: =COUNTIFS($A$5:$A$104,A19,$W$5:$W$104,">"&W19)+1 -> 11 | Y19: Opción parcial / revisar alcance | Z19: Tiene cobertura razonable para el alcance actual. | AA19: El presupuesto encaja con su rango habitual. | AB19: Puede acompañar a una MiPyme que aún está aterrizando el encargo. | AC19: No cubre de forma sólida uno de los frentes solicitados; podría requerir segundo perfil o alcance por fases.
A20: M01 | B20: Café de Barrio | C20: C16 | D20: David Londoño | E20: 0.5 | F20: 0 | G20: 0.35 | H20: 0.7 | I20: 0.95 | J20: 0.9 | K20: 0.72 | L20: 1 | M20: 0.95 | N20: 7.65 | O20: =E20*Criterios_Match!$C$5 -> 15 | P20: =G20*Criterios_Match!$C$6 -> 6.3 | Q20: =H20*Criterios_Match!$C$7 -> 9.8 | R20: =I20*Criterios_Match!$C$8 -> 13.3 | S20: =J20*Criterios_Match!$C$9 -> 8.1 | T20: =K20*Criterios_Match!$C$10 -> 4.32 | U20: =L20*Criterios_Match!$C$11 -> 4 | V20: =M20*Criterios_Match!$C$12 -> 4.75 | W20: =ROUND(SUM(O20:V20)+N20,2) -> 73.22 | X20: =COUNTIFS($A$5:$A$104,A20,$W$5:$W$104,">"&W20)+1 -> 13 | Y20: Opción parcial / revisar alcance | Z20: Tiene cobertura razonable para el alcance actual. | AA20: Ya ha trabajado en Gastronomía / alimentos. | AB20: Tiene mejor probabilidad de responder al plazo. | AC20: No cubre de forma sólida uno de los frentes solicitados; podría requerir segundo perfil o alcance por fases.
A21: M01 | B21: Café de Barrio | C21: C17 | D21: Manuela Arango | E21: 0.2 | F21: 0 | G21: 0.35 | H21: 0.92 | I21: 0.95 | J21: 1 | K21: 1 | L21: 1 | M21: 0.95 | N21: 8.61 | O21: =E21*Criterios_Match!$C$5 -> 6 | P21: =G21*Criterios_Match!$C$6 -> 6.3 | Q21: =H21*Criterios_Match!$C$7 -> 12.88 | R21: =I21*Criterios_Match!$C$8 -> 13.3 | S21: =J21*Criterios_Match!$C$9 -> 9 | T21: =K21*Criterios_Match!$C$10 -> 6 | U21: =L21*Criterios_Match!$C$11 -> 4 | V21: =M21*Criterios_Match!$C$12 -> 4.75 | W21: =ROUND(SUM(O21:V21)+N21,2) -> 70.84 | X21: =COUNTIFS($A$5:$A$104,A21,$W$5:$W$104,">"&W21)+1 -> 17 | Y21: Opción parcial / revisar alcance | Z21: Ya ha trabajado en Gastronomía / alimentos. | AA21: Puede acompañar a una MiPyme que aún está aterrizando el encargo. | AB21: Tiene mejor probabilidad de responder al plazo. | AC21: No cubre de forma sólida uno de los frentes solicitados; podría requerir segundo perfil o alcance por fases.
A22: M01 | B22: Café de Barrio | C22: C18 | D22: Esteban Quintero | E22: 0.52 | F22: 0 | G22: 0.75 | H22: 0.9 | I22: 0.3 | J22: 0.9 | K22: 0.9 | L22: 0.4 | M22: 1 | N22: 6.3 | O22: =E22*Criterios_Match!$C$5 -> 15.6 | P22: =G22*Criterios_Match!$C$6 -> 13.5 | Q22: =H22*Criterios_Match!$C$7 -> 12.6 | R22: =I22*Criterios_Match!$C$8 -> 4.2 | S22: =J22*Criterios_Match!$C$9 -> 8.1 | T22: =K22*Criterios_Match!$C$10 -> 5.4 | U22: =L22*Criterios_Match!$C$11 -> 1.6 | V22: =M22*Criterios_Match!$C$12 -> 5 | W22: =ROUND(SUM(O22:V22)+N22,2) -> 72.3 | X22: =COUNTIFS($A$5:$A$104,A22,$W$5:$W$104,">"&W22)+1 -> 14 | Y22: Opción parcial / revisar alcance | Z22: Tiene cobertura razonable para el alcance actual. | AA22: Ya ha trabajado en Gastronomía / alimentos. | AB22: El presupuesto encaja con su rango habitual. | AC22: No cubre de forma sólida uno de los frentes solicitados; podría requerir segundo perfil o alcance por fases.
A23: M01 | B23: Café de Barrio | C23: C19 | D23: Catalina Sierra | E23: 0.67 | F23: 0 | G23: 1 | H23: 0.94 | I23: 0.75 | J23: 0.25 | K23: 0.96 | L23: 1 | M23: 1 | N23: 5.82 | O23: =E23*Criterios_Match!$C$5 -> 20.1 | P23: =G23*Criterios_Match!$C$6 -> 18 | Q23: =H23*Criterios_Match!$C$7 -> 13.16 | R23: =I23*Criterios_Match!$C$8 -> 10.5 | S23: =J23*Criterios_Match!$C$9 -> 2.25 | T23: =K23*Criterios_Match!$C$10 -> 5.76 | U23: =L23*Criterios_Match!$C$11 -> 4 | V23: =M23*Criterios_Match!$C$12 -> 5 | W23: =ROUND(SUM(O23:V23)+N23,2) -> 84.59 | X23: =COUNTIFS($A$5:$A$104,A23,$W$5:$W$104,">"&W23)+1 -> 4 | Y23: Opción parcial / revisar alcance | Z23: Tiene cobertura razonable para el alcance actual. | AA23: El presupuesto encaja con su rango habitual. | AB23: Puede acompañar a una MiPyme que aún está aterrizando el encargo. | AC23: No cubre de forma sólida uno de los frentes solicitados; podría requerir segundo perfil o alcance por fases.
A24: M01 | B24: Café de Barrio | C24: C20 | D24: Tomás Jaramillo | E24: 0.25 | F24: 0 | G24: 0.75 | H24: 0.94 | I24: 0.7 | J24: 0.9 | K24: 1 | L24: 0.4 | M24: 0.95 | N24: 7.62 | O24: =E24*Criterios_Match!$C$5 -> 7.5 | P24: =G24*Criterios_Match!$C$6 -> 13.5 | Q24: =H24*Criterios_Match!$C$7 -> 13.16 | R24: =I24*Criterios_Match!$C$8 -> 9.8 | S24: =J24*Criterios_Match!$C$9 -> 8.1 | T24: =K24*Criterios_Match!$C$10 -> 6 | U24: =L24*Criterios_Match!$C$11 -> 1.6 | V24: =M24*Criterios_Match!$C$12 -> 4.75 | W24: =ROUND(SUM(O24:V24)+N24,2) -> 72.03 | X24: =COUNTIFS($A$5:$A$104,A24,$W$5:$W$104,">"&W24)+1 -> 15 | Y24: Opción parcial / revisar alcance | Z24: Ya ha trabajado en Gastronomía / alimentos. | AA24: El presupuesto encaja con su rango habitual. | AB24: Puede acompañar a una MiPyme que aún está aterrizando el encargo. | AC24: No cubre de forma sólida uno de los frentes solicitados; podría requerir segundo perfil o alcance por fases.
A25: M02 | B25: Dermalab Natural | C25: C01 | D25: Ana Torres | E25: 0.82 | F25: 0.45 | G25: 0.75 | H25: 1 | I25: 0.91 | J25: 0.25 | K25: 1 | L25: 1 | M25: 1 | N25: 4.25 | O25: =E25*Criterios_Match!$C$5 -> 24.6 | P25: =G25*Criterios_Match!$C$6 -> 13.5 | Q25: =H25*Criterios_Match!$C$7 -> 14 | R25: =I25*Criterios_Match!$C$8 -> 12.74 | S25: =J25*Criterios_Match!$C$9 -> 2.25 | T25: =K25*Criterios_Match!$C$10 -> 6 | U25: =L25*Criterios_Match!$C$11 -> 4 | V25: =M25*Criterios_Match!$C$12 -> 5 | W25: =ROUND(SUM(O25:V25)+N25,2) -> 86.34 | X25: =COUNTIFS($A$5:$A$104,A25,$W$5:$W$104,">"&W25)+1 -> 3 | Y25: Candidato casi perfecto | Z25: Cubre bien 2/3 frentes del proyecto. | AA25: El presupuesto encaja con su rango habitual. | AB25: Su experiencia calza con la complejidad del proyecto. | AC25: Portafolio medido solo como señal pública, no como calidad real.
A26: M02 | B26: Dermalab Natural | C26: C02 | D26: Julián Mejía | E26: 0 | F26: 0 | G26: 0.75 | H26: 0.91 | I26: 0.98 | J26: 0.25 | K26: 0.9 | L26: 0.9 | M26: 0.95 | N26: 4.05 | O26: =E26*Criterios_Match!$C$5 -> 0 | P26: =G26*Criterios_Match!$C$6 -> 13.5 | Q26: =H26*Criterios_Match!$C$7 -> 12.74 | R26: =I26*Criterios_Match!$C$8 -> 13.72 | S26: =J26*Criterios_Match!$C$9 -> 2.25 | T26: =K26*Criterios_Match!$C$10 -> 5.4 | U26: =L26*Criterios_Match!$C$11 -> 3.6 | V26: =M26*Criterios_Match!$C$12 -> 4.75 | W26: =ROUND(SUM(O26:V26)+N26,2) -> 60.01 | X26: =COUNTIFS($A$5:$A$104,A26,$W$5:$W$104,">"&W26)+1 -> 17 | Y26: Opción parcial / revisar alcance | Z26: El presupuesto encaja con su rango habitual. | AA26: Su experiencia calza con la complejidad del proyecto. | AC26: No cubre de forma sólida uno de los frentes solicitados; podría requerir segundo perfil o alcance por fases. | Portafolio medido solo como señal pública, no como calidad real.
A27: M02 | B27: Dermalab Natural | C27: C03 | D27: Laura Ospina | E27: 0.38 | F27: 0 | G27: 1 | H27: 0.99 | I27: 0.98 | J27: 0.25 | K27: 1 | L27: 0.85 | M27: 0.95 | N27: 4.25 | O27: =E27*Criterios_Match!$C$5 -> 11.4 | P27: =G27*Criterios_Match!$C$6 -> 18 | Q27: =H27*Criterios_Match!$C$7 -> 13.86 | R27: =I27*Criterios_Match!$C$8 -> 13.72 | S27: =J27*Criterios_Match!$C$9 -> 2.25 | T27: =K27*Criterios_Match!$C$10 -> 6 | U27: =L27*Criterios_Match!$C$11 -> 3.4 | V27: =M27*Criterios_Match!$C$12 -> 4.75 | W27: =ROUND(SUM(O27:V27)+N27,2) -> 77.63 | X27: =COUNTIFS($A$5:$A$104,A27,$W$5:$W$104,">"&W27)+1 -> 10 | Y27: Opción parcial / revisar alcance | Z27: El presupuesto encaja con su rango habitual. | AA27: Su experiencia calza con la complejidad del proyecto. | AC27: No cubre de forma sólida uno de los frentes solicitados; podría requerir segundo perfil o alcance por fases. | Portafolio medido solo como señal pública, no como calidad real.
A28: M02 | B28: Dermalab Natural | C28: C04 | D28: Mateo Rojas | E28: 0.27 | F28: 0 | G28: 0.05 | H28: 0.95 | I28: 0.84 | J28: 0.25 | K28: 0.75 | L28: 0.85 | M28: 1 | N28: 3.75 | O28: =E28*Criterios_Match!$C$5 -> 8.1 | P28: =G28*Criterios_Match!$C$6 -> 0.9 | Q28: =H28*Criterios_Match!$C$7 -> 13.3 | R28: =I28*Criterios_Match!$C$8 -> 11.76 | S28: =J28*Criterios_Match!$C$9 -> 2.25 | T28: =K28*Criterios_Match!$C$10 -> 4.5 | U28: =L28*Criterios_Match!$C$11 -> 3.4 | V28: =M28*Criterios_Match!$C$12 -> 5 | W28: =ROUND(SUM(O28:V28)+N28,2) -> 52.96 | X28: =COUNTIFS($A$5:$A$104,A28,$W$5:$W$104,">"&W28)+1 -> 18 | Y28: Opción parcial / revisar alcance | Z28: Cumple de forma equilibrada entre servicio, proceso y presupuesto. | AC28: No cubre de forma sólida uno de los frentes solicitados; podría requerir segundo perfil o alcance por fases. | Portafolio medido solo como señal pública, no como calidad real.
A29: M02 | B29: Dermalab Natural | C29: C05 | D29: Valentina Ruiz | E29: 0.75 | F29: 0.25 | G29: 1 | H29: 0.94 | I29: 0.98 | J29: 0.25 | K29: 0.9 | L29: 0.95 | M29: 0.85 | N29: 4.05 | O29: =E29*Criterios_Match!$C$5 -> 22.5 | P29: =G29*Criterios_Match!$C$6 -> 18 | Q29: =H29*Criterios_Match!$C$7 -> 13.16 | R29: =I29*Criterios_Match!$C$8 -> 13.72 | S29: =J29*Criterios_Match!$C$9 -> 2.25 | T29: =K29*Criterios_Match!$C$10 -> 5.4 | U29: =L29*Criterios_Match!$C$11 -> 3.8 | V29: =M29*Criterios_Match!$C$12 -> 4.25 | W29: =ROUND(SUM(O29:V29)+N29,2) -> 87.13 | X29: =COUNTIFS($A$5:$A$104,A29,$W$5:$W$104,">"&W29)+1 -> 2 | Y29: Candidato fuerte con revisión manual | Z29: Cubre bien 2/3 frentes del proyecto. | AA29: El presupuesto encaja con su rango habitual. | AB29: Su experiencia calza con la complejidad del proyecto. | AC29: No cubre de forma sólida uno de los frentes solicitados; podría requerir segundo perfil o alcance por fases. | Portafolio medido solo como señal pública, no como calidad real.
A30: M02 | B30: Dermalab Natural | C30: C06 | D30: Camilo Herrera | E30: 0 | F30: 0 | G30: 0.35 | H30: 0.86 | I30: 0.98 | J30: 0.25 | K30: 0.6 | L30: 0.9 | M30: 0.95 | N30: 3.45 | O30: =E30*Criterios_Match!$C$5 -> 0 | P30: =G30*Criterios_Match!$C$6 -> 6.3 | Q30: =H30*Criterios_Match!$C$7 -> 12.04 | R30: =I30*Criterios_Match!$C$8 -> 13.72 | S30: =J30*Criterios_Match!$C$9 -> 2.25 | T30: =K30*Criterios_Match!$C$10 -> 3.6 | U30: =L30*Criterios_Match!$C$11 -> 3.6 | V30: =M30*Criterios_Match!$C$12 -> 4.75 | W30: =ROUND(SUM(O30:V30)+N30,2) -> 49.71 | X30: =COUNTIFS($A$5:$A$104,A30,$W$5:$W$104,">"&W30)+1 -> 19 | Y30: Opción parcial / revisar alcance | Z30: Cumple de forma equilibrada entre servicio, proceso y presupuesto. | AC30: No cubre de forma sólida uno de los frentes solicitados; podría requerir segundo perfil o alcance por fases. | Portafolio medido solo como señal pública, no como calidad real.
A31: M02 | B31: Dermalab Natural | C31: C07 | D31: Sofía Marín | E31: 0.38 | F31: 0 | G31: 0.75 | H31: 0.97 | I31: 0.91 | J31: 1 | K31: 1 | L31: 0.85 | M31: 1 | N31: 6.5 | O31: =E31*Criterios_Match!$C$5 -> 11.4 | P31: =G31*Criterios_Match!$C$6 -> 13.5 | Q31: =H31*Criterios_Match!$C$7 -> 13.58 | R31: =I31*Criterios_Match!$C$8 -> 12.74 | S31: =J31*Criterios_Match!$C$9 -> 9 | T31: =K31*Criterios_Match!$C$10 -> 6 | U31: =L31*Criterios_Match!$C$11 -> 3.4 | V31: =M31*Criterios_Match!$C$12 -> 5 | W31: =ROUND(SUM(O31:V31)+N31,2) -> 81.12 | X31: =COUNTIFS($A$5:$A$104,A31,$W$5:$W$104,">"&W31)+1 -> 7 | Y31: Opción parcial / revisar alcance | Z31: Ya ha trabajado en Salud / bienestar. | AA31: El presupuesto encaja con su rango habitual. | AB31: Su experiencia calza con la complejidad del proyecto. | AC31: No cubre de forma sólida uno de los frentes solicitados; podría requerir segundo perfil o alcance por fases. | Portafolio medido solo como señal pública, no como calidad real.
A32: M02 | B32: Dermalab Natural | C32: C08 | D32: Nicolás Pardo | E32: 0.12 | F32: 0 | G32: 0.75 | H32: 0.91 | I32: 0.91 | J32: 0.9 | K32: 0.9 | L32: 0.95 | M32: 1 | N32: 6 | O32: =E32*Criterios_Match!$C$5 -> 3.6 | P32: =G32*Criterios_Match!$C$6 -> 13.5 | Q32: =H32*Criterios_Match!$C$7 -> 12.74 | R32: =I32*Criterios_Match!$C$8 -> 12.74 | S32: =J32*Criterios_Match!$C$9 -> 8.1 | T32: =K32*Criterios_Match!$C$10 -> 5.4 | U32: =L32*Criterios_Match!$C$11 -> 3.8 | V32: =M32*Criterios_Match!$C$12 -> 5 | W32: =ROUND(SUM(O32:V32)+N32,2) -> 70.88 | X32: =COUNTIFS($A$5:$A$104,A32,$W$5:$W$104,">"&W32)+1 -> 15 | Y32: Opción parcial / revisar alcance | Z32: Ya ha trabajado en Salud / bienestar. | AA32: El presupuesto encaja con su rango habitual. | AB32: Su experiencia calza con la complejidad del proyecto. | AC32: No cubre de forma sólida uno de los frentes solicitados; podría requerir segundo perfil o alcance por fases. | Portafolio medido solo como señal pública, no como calidad real.
A33: M02 | B33: Dermalab Natural | C33: C09 | D33: Daniela Vélez | E33: 0.57 | F33: 0.25 | G33: 0.75 | H33: 0.97 | I33: 0.98 | J33: 0.25 | K33: 1 | L33: 0.85 | M33: 0.95 | N33: 4.25 | O33: =E33*Criterios_Match!$C$5 -> 17.1 | P33: =G33*Criterios_Match!$C$6 -> 13.5 | Q33: =H33*Criterios_Match!$C$7 -> 13.58 | R33: =I33*Criterios_Match!$C$8 -> 13.72 | S33: =J33*Criterios_Match!$C$9 -> 2.25 | T33: =K33*Criterios_Match!$C$10 -> 6 | U33: =L33*Criterios_Match!$C$11 -> 3.4 | V33: =M33*Criterios_Match!$C$12 -> 4.75 | W33: =ROUND(SUM(O33:V33)+N33,2) -> 78.55 | X33: =COUNTIFS($A$5:$A$104,A33,$W$5:$W$104,">"&W33)+1 -> 9 | Y33: Opción parcial / revisar alcance | Z33: Tiene cobertura razonable para el alcance actual. | AA33: El presupuesto encaja con su rango habitual. | AB33: Su experiencia calza con la complejidad del proyecto. | AC33: No cubre de forma sólida uno de los frentes solicitados; podría requerir segundo perfil o alcance por fases. | Portafolio medido solo como señal pública, no como calidad real.
A34: M02 | B34: Dermalab Natural | C34: C10 | D34: Felipe Gómez | E34: 0.47 | F34: 0 | G34: 0.75 | H34: 0.92 | I34: 0.91 | J34: 0.25 | K34: 0.98 | L34: 0.95 | M34: 1 | N34: 4.21 | O34: =E34*Criterios_Match!$C$5 -> 14.1 | P34: =G34*Criterios_Match!$C$6 -> 13.5 | Q34: =H34*Criterios_Match!$C$7 -> 12.88 | R34: =I34*Criterios_Match!$C$8 -> 12.74 | S34: =J34*Criterios_Match!$C$9 -> 2.25 | T34: =K34*Criterios_Match!$C$10 -> 5.88 | U34: =L34*Criterios_Match!$C$11 -> 3.8 | V34: =M34*Criterios_Match!$C$12 -> 5 | W34: =ROUND(SUM(O34:V34)+N34,2) -> 74.36 | X34: =COUNTIFS($A$5:$A$104,A34,$W$5:$W$104,">"&W34)+1 -> 12 | Y34: Opción parcial / revisar alcance | Z34: Tiene cobertura razonable para el alcance actual. | AA34: El presupuesto encaja con su rango habitual. | AB34: Su experiencia calza con la complejidad del proyecto. | AC34: No cubre de forma sólida uno de los frentes solicitados; podría requerir segundo perfil o alcance por fases. | Portafolio medido solo como señal pública, no como calidad real.
A35: M02 | B35: Dermalab Natural | C35: C11 | D35: Mariana Salcedo | E35: 0.82 | F35: 0.45 | G35: 0.35 | H35: 0.97 | I35: 0.91 | J35: 0.9 | K35: 0.75 | L35: 1 | M35: 1 | N35: 5.7 | O35: =E35*Criterios_Match!$C$5 -> 24.6 | P35: =G35*Criterios_Match!$C$6 -> 6.3 | Q35: =H35*Criterios_Match!$C$7 -> 13.58 | R35: =I35*Criterios_Match!$C$8 -> 12.74 | S35: =J35*Criterios_Match!$C$9 -> 8.1 | T35: =K35*Criterios_Match!$C$10 -> 4.5 | U35: =L35*Criterios_Match!$C$11 -> 4 | V35: =M35*Criterios_Match!$C$12 -> 5 | W35: =ROUND(SUM(O35:V35)+N35,2) -> 84.52 | X35: =COUNTIFS($A$5:$A$104,A35,$W$5:$W$104,">"&W35)+1 -> 4 | Y35: Candidato fuerte con revisión manual | Z35: Cubre bien 2/3 frentes del proyecto. | AA35: Ya ha trabajado en Salud / bienestar. | AC35: Portafolio medido solo como señal pública, no como calidad real.
A36: M02 | B36: Dermalab Natural | C36: C12 | D36: Andrés Buitrago | E36: 0.12 | F36: 0 | G36: 1 | H36: 0.96 | I36: 0.98 | J36: 0.25 | K36: 1 | L36: 0.85 | M36: 1 | N36: 4.25 | O36: =E36*Criterios_Match!$C$5 -> 3.6 | P36: =G36*Criterios_Match!$C$6 -> 18 | Q36: =H36*Criterios_Match!$C$7 -> 13.44 | R36: =I36*Criterios_Match!$C$8 -> 13.72 | S36: =J36*Criterios_Match!$C$9 -> 2.25 | T36: =K36*Criterios_Match!$C$10 -> 6 | U36: =L36*Criterios_Match!$C$11 -> 3.4 | V36: =M36*Criterios_Match!$C$12 -> 5 | W36: =ROUND(SUM(O36:V36)+N36,2) -> 69.66 | X36: =COUNTIFS($A$5:$A$104,A36,$W$5:$W$104,">"&W36)+1 -> 16 | Y36: Opción parcial / revisar alcance | Z36: El presupuesto encaja con su rango habitual. | AA36: Su experiencia calza con la complejidad del proyecto. | AC36: No cubre de forma sólida uno de los frentes solicitados; podría requerir segundo perfil o alcance por fases. | Portafolio medido solo como señal pública, no como calidad real.
A37: M02 | B37: Dermalab Natural | C37: C13 | D37: Paula Restrepo | E37: 0.57 | F37: 0.25 | G37: 0.75 | H37: 0.92 | I37: 0.98 | J37: 0.25 | K37: 0.83 | L37: 1 | M37: 0.95 | N37: 3.91 | O37: =E37*Criterios_Match!$C$5 -> 17.1 | P37: =G37*Criterios_Match!$C$6 -> 13.5 | Q37: =H37*Criterios_Match!$C$7 -> 12.88 | R37: =I37*Criterios_Match!$C$8 -> 13.72 | S37: =J37*Criterios_Match!$C$9 -> 2.25 | T37: =K37*Criterios_Match!$C$10 -> 4.98 | U37: =L37*Criterios_Match!$C$11 -> 4 | V37: =M37*Criterios_Match!$C$12 -> 4.75 | W37: =ROUND(SUM(O37:V37)+N37,2) -> 77.09 | X37: =COUNTIFS($A$5:$A$104,A37,$W$5:$W$104,">"&W37)+1 -> 11 | Y37: Opción parcial / revisar alcance | Z37: Tiene cobertura razonable para el alcance actual. | AA37: El presupuesto encaja con su rango habitual. | AC37: No cubre de forma sólida uno de los frentes solicitados; podría requerir segundo perfil o alcance por fases. | Portafolio medido solo como señal pública, no como calidad real.
A38: M02 | B38: Dermalab Natural | C38: C14 | D38: Sergio Cárdenas | E38: 0.38 | F38: 0 | G38: 0.75 | H38: 0.98 | I38: 0.91 | J38: 0.25 | K38: 1 | L38: 1 | M38: 1 | N38: 4.25 | O38: =E38*Criterios_Match!$C$5 -> 11.4 | P38: =G38*Criterios_Match!$C$6 -> 13.5 | Q38: =H38*Criterios_Match!$C$7 -> 13.72 | R38: =I38*Criterios_Match!$C$8 -> 12.74 | S38: =J38*Criterios_Match!$C$9 -> 2.25 | T38: =K38*Criterios_Match!$C$10 -> 6 | U38: =L38*Criterios_Match!$C$11 -> 4 | V38: =M38*Criterios_Match!$C$12 -> 5 | W38: =ROUND(SUM(O38:V38)+N38,2) -> 72.86 | X38: =COUNTIFS($A$5:$A$104,A38,$W$5:$W$104,">"&W38)+1 -> 13 | Y38: Opción parcial / revisar alcance | Z38: El presupuesto encaja con su rango habitual. | AA38: Su experiencia calza con la complejidad del proyecto. | AC38: No cubre de forma sólida uno de los frentes solicitados; podría requerir segundo perfil o alcance por fases. | Portafolio medido solo como señal pública, no como calidad real.
A39: M02 | B39: Dermalab Natural | C39: C15 | D39: Luisa Fernanda Gil | E39: 0.38 | F39: 0 | G39: 0.75 | H39: 0.99 | I39: 0.98 | J39: 1 | K39: 0.98 | L39: 0.85 | M39: 0.95 | N39: 6.46 | O39: =E39*Criterios_Match!$C$5 -> 11.4 | P39: =G39*Criterios_Match!$C$6 -> 13.5 | Q39: =H39*Criterios_Match!$C$7 -> 13.86 | R39: =I39*Criterios_Match!$C$8 -> 13.72 | S39: =J39*Criterios_Match!$C$9 -> 9 | T39: =K39*Criterios_Match!$C$10 -> 5.88 | U39: =L39*Criterios_Match!$C$11 -> 3.4 | V39: =M39*Criterios_Match!$C$12 -> 4.75 | W39: =ROUND(SUM(O39:V39)+N39,2) -> 81.97 | X39: =COUNTIFS($A$5:$A$104,A39,$W$5:$W$104,">"&W39)+1 -> 6 | Y39: Opción parcial / revisar alcance | Z39: Ya ha trabajado en Salud / bienestar. | AA39: El presupuesto encaja con su rango habitual. | AB39: Su experiencia calza con la complejidad del proyecto. | AC39: No cubre de forma sólida uno de los frentes solicitados; podría requerir segundo perfil o alcance por fases. | Portafolio medido solo como señal pública, no como calidad real.
A40: M02 | B40: Dermalab Natural | C40: C16 | D40: David Londoño | E40: 0 | F40: 0 | G40: 0.05 | H40: 0.85 | I40: 0.98 | J40: 0.9 | K40: 0.3 | L40: 0.9 | M40: 0.95 | N40: 4.8 | O40: =E40*Criterios_Match!$C$5 -> 0 | P40: =G40*Criterios_Match!$C$6 -> 0.9 | Q40: =H40*Criterios_Match!$C$7 -> 11.9 | R40: =I40*Criterios_Match!$C$8 -> 13.72 | S40: =J40*Criterios_Match!$C$9 -> 8.1 | T40: =K40*Criterios_Match!$C$10 -> 1.8 | U40: =L40*Criterios_Match!$C$11 -> 3.6 | V40: =M40*Criterios_Match!$C$12 -> 4.75 | W40: =ROUND(SUM(O40:V40)+N40,2) -> 49.57 | X40: =COUNTIFS($A$5:$A$104,A40,$W$5:$W$104,">"&W40)+1 -> 20 | Y40: Opción parcial / revisar alcance | Z40: Ya ha trabajado en Salud / bienestar. | AC40: No cubre de forma sólida uno de los frentes solicitados; podría requerir segundo perfil o alcance por fases. | Portafolio medido solo como señal pública, no como calidad real.
A41: M02 | B41: Dermalab Natural | C41: C17 | D41: Manuela Arango | E41: 0.75 | F41: 0.25 | G41: 0.75 | H41: 0.96 | I41: 0.98 | J41: 0.25 | K41: 1 | L41: 0.95 | M41: 0.95 | N41: 4.25 | O41: =E41*Criterios_Match!$C$5 -> 22.5 | P41: =G41*Criterios_Match!$C$6 -> 13.5 | Q41: =H41*Criterios_Match!$C$7 -> 13.44 | R41: =I41*Criterios_Match!$C$8 -> 13.72 | S41: =J41*Criterios_Match!$C$9 -> 2.25 | T41: =K41*Criterios_Match!$C$10 -> 6 | U41: =L41*Criterios_Match!$C$11 -> 3.8 | V41: =M41*Criterios_Match!$C$12 -> 4.75 | W41: =ROUND(SUM(O41:V41)+N41,2) -> 84.21 | X41: =COUNTIFS($A$5:$A$104,A41,$W$5:$W$104,">"&W41)+1 -> 5 | Y41: Candidato fuerte con revisión manual | Z41: Cubre bien 2/3 frentes del proyecto. | AA41: El presupuesto encaja con su rango habitual. | AB41: Su experiencia calza con la complejidad del proyecto. | AC41: No cubre de forma sólida uno de los frentes solicitados; podría requerir segundo perfil o alcance por fases. | Portafolio medido solo como señal pública, no como calidad real.
...

Sheet Top3_por_MiPyme
A1: Top 3 sugerido por cada MiPyme
A2: Lista corta para demo del MVP. Úsala como salida visible del botón 'Ver creativos sugeridos'.
A4: MiPyme_ID | B4: Empresa | C4: Rank | D4: Creativo_ID | E4: Creativo | F4: Score | G4: Estado | H4: Razón 1 | I4: Razón 2 | J4: Cautela
A5: M01 | B5: Café de Barrio | C5: 1 | D5: C14 | E5: Sergio Cárdenas | F5: 86.65 | G5: Opción parcial / revisar alcance | H5: Tiene cobertura razonable para el alcance actual. | I5: Ya ha trabajado en Gastronomía / alimentos. | J5: No cubre de forma sólida uno de los frentes solicitados; podría requerir segundo perfil o alcance por fases.
A6: M01 | B6: Café de Barrio | C6: 2 | D6: C02 | E6: Julián Mejía | F6: 82.7 | G6: Opción parcial / revisar alcance | H6: Tiene cobertura razonable para el alcance actual. | I6: Ya ha trabajado en Gastronomía / alimentos. | J6: No cubre de forma sólida uno de los frentes solicitados; podría requerir segundo perfil o alcance por fases.
A7: M01 | B7: Café de Barrio | C7: 3 | D7: C10 | E7: Felipe Gómez | F7: 81.36 | G7: Opción parcial / revisar alcance | H7: Tiene cobertura razonable para el alcance actual. | I7: Ya ha trabajado en Gastronomía / alimentos. | J7: No cubre de forma sólida uno de los frentes solicitados; podría requerir segundo perfil o alcance por fases.
A8: M02 | B8: Dermalab Natural | C8: 1 | D8: C20 | E8: Tomás Jaramillo | F8: 83.47 | G8: Candidato fuerte con revisión manual | H8: Tiene cobertura razonable para el alcance actual. | I8: Ya ha trabajado en Salud / bienestar. | J8: No cubre de forma sólida uno de los frentes solicitados; podría requerir segundo perfil o alcance por fases. | Portafolio medido solo como señal pública, no como calidad real.
A9: M02 | B9: Dermalab Natural | C9: 2 | D9: C05 | E9: Valentina Ruiz | F9: 78.67 | G9: Candidato fuerte con revisión manual | H9: Cubre bien 2/3 frentes del proyecto. | I9: El presupuesto encaja con su rango habitual. | J9: No cubre de forma sólida uno de los frentes solicitados; podría requerir segundo perfil o alcance por fases. | Portafolio medido solo como señal pública, no como calidad real.
A10: M02 | B10: Dermalab Natural | C10: 3 | D10: C01 | E10: Ana Torres | F10: 78.1 | G10: Candidato casi perfecto | H10: Cubre bien 2/3 frentes del proyecto. | I10: El presupuesto encaja con su rango habitual. | J10: Portafolio medido solo como señal pública, no como calidad real.
A11: M03 | B11: EduPlay Lab | C11: 1 | D11: C15 | E11: Luisa Fernanda Gil | F11: 89.45 | G11: Candidato casi perfecto | H11: Cubre bien 3/3 frentes del proyecto. | I11: Ya ha trabajado en Educación. | J11: Presupuesto aún indefinido; validar alcance antes de cerrar match.
A12: M03 | B12: EduPlay Lab | C12: 2 | D12: C03 | E12: Laura Ospina | F12: 88.83 | G12: Candidato casi perfecto | H12: Cubre bien 3/3 frentes del proyecto. | I12: Ya ha trabajado en Educación. | J12: Presupuesto aún indefinido; validar alcance antes de cerrar match.
A13: M03 | B13: EduPlay Lab | C13: 3 | D13: C11 | E13: Mariana Salcedo | F13: 81.09 | G13: Opción parcial / revisar alcance | H13: Cubre bien 2/3 frentes del proyecto. | I13: Ya ha trabajado en Educación. | J13: No cubre de forma sólida uno de los frentes solicitados; podría requerir segundo perfil o alcance por fases. | Presupuesto aún indefinido; validar alcance antes de cerrar match.
